Workbook

Sheet NOMINAS_ACTIVAS
A5: 80185
A6: 205737
A7: 206105
A8: 20985
A9: 5055
A10: 206295
A11: 206297
A12: 206252
A13: 6325
A14: 206309
A15: 206310
A16: 206317
... A81: 5098
A82: 206338
A83: 427
A84: 6058
A85: 5913
A86: 6283
A87: 555
A88: 205454
A89: 5803
A90: 5949
A91: 303
A92: 5537
A93: 6218
A94: 5352
... A346: 3974
A347: 2027
A348: 3970
A349: 2028
A350: 1997
A351: 3973
A352: 3979
A353: 3990
A354: 2029
A355: 3897
A356: 2030
A357: 2019
A358: 2023
A359: 3967
...

Sheet  PLAN Y PROGRAMA ANUAL 2026
T3: Gerencia Metropolitana Norte
T4: Subgerencia de Administración y Finanzas
T5: Departamento de Relaciones Industriales
T6: Capacitación, Adiestramiento y Productividad
A13: COMISION MIXTA DE CAPACITACIÓN, ADIESTRAMIENTO Y PRODUCTIVIDAD
A14: PERIODO: 01 DE ENERO AL 31 DE DICIEMBRE DEL 2026
A15: PLAN Y PROGRAMA DE CAPACITACIÓN, ADIESTRAMIENTO Y PRODUCTIVIDAD / FORMATO DC-2
A17: NO | B17: CENTRO DE COSTOS | C17: PUESTO | D17: NÓMINA | E17: NOMBRE DEL TRABAJADOR | F17: ÁREA | G17: CURP | H17: INDUCCIÓN | I17: Columna1 | J17: Columna2 | K17: CAPACITACIÒN | L17: Columna3 | M17: Columna4 | N17: MODALIDAD DEL CURSO | O17: NOMBRE DEL CURSO | P17: FI | Q17: FT | R17: D | S17: GÉNERO | T17: C/S COSTO | U17: TOTAL DE HORAS
H18: FI | I18: FT | J18: D | K18: FI | L18: FT | M18: D
A19: 1 | B19: 301 | C19: GERENTE | D19: 80185 | E19: MARCO ANTONIO VILCHIS LARA | F19: GERENCIA | G19: VILM820421HDFLRR03 | S19: H | U19: =SUM(' PLAN Y PROGRAMA ANUAL 2026'!$R19:$R19) -> 0
A20: {=IF(B20<>"",COUNTIF($B$19:B20,"<>"),"")} -> 2 | B20: 301 | C20: JEFE DE OFICINA | D20: 205737 | E20: ESQUIVEL DE LA CRUZ ESTHELA | F20: GERENCIA | G20: EUCE641228MMCSRS01 | S20: M | T20: =IFERROR(VLOOKUP(O20, '[1]CURSOS 2025'!A:B, 2, FALSE), "") | U20: =SUM(' PLAN Y PROGRAMA ANUAL 2026'!$R20:$R20) -> 0
A21: {=IF(B21<>"",COUNTIF($B$19:B21,"<>"),"")} -> 3 | B21: 301 | C21: JEFE DE UNIDAD | D21: 206786 | E21: BAEZ BRENES ALICIA MICHEL | F21: GERENCIA | G21: BABA000128MMCZRLA6 | S21: M | T21: =IFERROR(VLOOKUP(O21, '[1]CURSOS 2025'!A:B, 2, FALSE), "") | U21: =SUM(' PLAN Y PROGRAMA ANUAL 2026'!$R21) -> 0
A22: {=IF(B22<>"",COUNTIF($B$19:B22,"<>"),"")} -> 4 | B22: 317 | C22: COORDINADOR GENERAL | D22: 20985 | E22: SUAREZ RODRÍGUEZ MARINO | F22: GERENCIA | G22: SURM691226HVZRDR02 | K22: X | L22: X | M22: X | N22: EN LINEA | O22: ACCIONES PARA ABORDAR RIESGOS Y OPORTUNIDADES | P22: 46069 | Q22: 46069 | R22: 2 | S22: H | T22: S/COSTO | U22: =SUM(R22:R25) -> 8
A23: {=IF(B23<>"",COUNTIF($B$19:B23,"<>"),"")} | K23: X | L23: X | M23: X | N23: EN LINEA | O23: ISO 9001 : 2026 Y SUS NUEVOS REQUERIMENTOS | P23: 46071 | Q23: 46071 | R23: 2 | S23: H | T23: S/COSTO
A24: {=IF(B24<>"",COUNTIF($B$19:B24,"<>"),"")} | K24: X | L24: X | M24: X | N24: EN LINEA | O24: CONTROL DE LA INFORMACIÓN DOCUMENTADA | P24: 46071 | Q24: 46071 | R24: 2 | S24: H | T24: S/COSTO
A25: {=IF(B25<>"",COUNTIF($B$19:B25,"<>"),"")} | K25: X | L25: X | M25: X | N25: EN LINEA | O25: CUMPLIMIENTO DEL REQUISITO CALIBRACIÓN DE INSTRUMENTOS DE MEDICIÓN | P25: 46073 | Q25: 46073 | R25: 2 | S25: H | T25: S/COSTO
A26: {=IF(B26<>"",COUNTIF($B$19:B26,"<>"),"")}
A27: {=IF(B27<>"",COUNTIF($B$19:B27,"<>"),"")} -> 5 | B27: 317 | C27: AUXILIAR ADMINISTRATIVO | D27: 206252 | E27: MORA SÁNCHEZ CARLA ANDREA | F27: DEPARTAMENTO DE CONTROL DE CALIDAD | G27: MOSC951225MDFRNR02 | S27: M | U27: =SUM(' PLAN Y PROGRAMA ANUAL 2026'!$R27:$R27) -> 0
A28: {=IF(B28<>"",COUNTIF($B$19:B28,"<>"),"")} -> 6 | B28: 317 | C28: QUIMICO | D28: 206105 | E28: LÓPEZ HERNÁNDEZ MARISOL | F28: DEPARTAMENTO DE CONTROL DE CALIDAD | G28: LOHM830715MSLPRR01 | K28: X | L28: X | M28: X | N28: EN LINEA | O28: ACCIONES PARA ABORDAR RIESGOS Y OPORTUNIDADES | P28: 46069 | Q28: 46069 | R28: 2 | S28: M | T28: S/COSTO | U28: =SUM(' PLAN Y PROGRAMA ANUAL 2026'!$R28:$R30) -> 6
A29: {=IF(B29<>"",COUNTIF($B$19:B29,"<>"),"")} | K29: X | L29: X | M29: X | N29: EN LINEA | O29: ISO 9001 : 2026 Y SUS NUEVOS REQUERIMENTOS | P29: 46071 | Q29: 46071 | R29: 2 | S29: M | T29: S/COSTO
A30: {=IF(B30<>"",COUNTIF($B$19:B30,"<>"),"")} | K30: X | L30: X | M30: X | N30: EN LINEA | O30: CUMPLIMIENTO DEL REQUISITO CALIBRACIÓN DE INSTRUMENTOS DE MEDICIÓN | P30: 46073 | Q30: 46073 | R30: 2 | S30: M | T30: S/COSTO
A31: {=IF(B31<>"",COUNTIF($B$19:B31,"<>"),"")} -> 7 | B31: 317 | C31: TECNICO QUÍMICO | D31: 206108 | E31: RANGEL DÍAZ RAUL | F31: DEPARTAMENTO DE CONTROL DE CALIDAD | G31: RADR640901HDFNZL05 | S31: H | T31: =IFERROR(VLOOKUP(O31, '[1]CURSOS 2025'!A:B, 2, FALSE), "") | U31: =SUM(' PLAN Y PROGRAMA ANUAL 2026'!$R31:$R31) -> 0
A32: {=IF(B32<>"",COUNTIF($B$19:B32,"<>"),"")} -> 8 | B32: 317 | C32: SECRETARIA DE COORDINACION | D32: 6178 | E32: MONROY ENRIQUEZ MARIEL NAYELY | F32: DEPARTAMENTO DE CONTROL DE CALIDAD | G32: MOEM901108MDFNNR06 | S32: M | T32: =IFERROR(VLOOKUP(O32, '[1]CURSOS 2025'!A:B, 2, FALSE), "") | U32: =SUM(' PLAN Y PROGRAMA ANUAL 2026'!$R32) -> 0
A33: {=IF(B33<>"",COUNTIF($B$19:B33,"<>"),"")} -> 9 | B33: 317 | C33: AUXILIAR ADMINISTRATIVO | D33: 6190 | E33: CORTES AGUILERA ARELI YAZMIN | F33: DEPARTAMENTO DE CONTROL DE CALIDAD | G33: COAA950711MDFRGR07 | S33: M | T33: =IFERROR(VLOOKUP(O33, '[1]CURSOS 2025'!A:B, 2, FALSE), "") | U33: =SUM(' PLAN Y PROGRAMA ANUAL 2026'!$R33:$R33) -> 0
A34: {=IF(B34<>"",COUNTIF($B$19:B34,"<>"),"")} -> 10 | B34: 317 | C34: TECNICO QUIMICO | D34: 206225 | E34: RAMÍREZ AMADOR RODOLFO ALBERTO | F34: DEPARTAMENTO DE CONTROL DE CALIDAD | G34: RAAR920117HDFMMD06 | K34: X | L34: X | M34: X | N34: EN LINEA | O34: CUMPLIMIENTO DEL REQUISITO CALIBRACIÓN DE INSTRUMENTOS DE MEDICIÓN | P34: 46073 | Q34: 46073 | R34: 2 | S34: H | T34: S/COSTO | U34: =SUM(R34:R34) -> 2
A35: {=IF(B35<>"",COUNTIF($B$19:B35,"<>"),"")} -> 11 | B35: 317 | C35: AYUDANTE DE LABORATORIO | D35: 3325 | E35: GUTIERREZ CRUZ JUAN CARLOS | F35: DEPARTAMENTO DE CONTROL DE CALIDAD | G35: GUCJ740518HDFTRN03 | K35: X | L35: X | M35: X | N35: EN LINEA | O35: EQUIPOS DE REFRIGERACIÓN Y AIRE ACONDICIONADO | P35: 46070 | Q35: 46070 | R35: 2 | S35: H | T35: S/COSTO | U35: =SUM(' PLAN Y PROGRAMA ANUAL 2026'!$R35:$R35) -> 2
A36: {=IF(B36<>"",COUNTIF($B$19:B36,"<>"),"")} -> 12 | B36: 317 | C36: AYUDANTE DE LABORATORIO | D36: 3282 | E36: GONZÁLEZ GLORIA MIGUEL | F36: DEPARTAMENTO DE CONTROL DE CALIDAD | G36: GOGM700207HGTNLG03 | S36: H | T36: =IFERROR(VLOOKUP(O36, '[1]CURSOS 2025'!A:B, 2, FALSE), "") | U36: =SUM(' PLAN Y PROGRAMA ANUAL 2026'!$R36) -> 0
A37: {=IF(B37<>"",COUNTIF($B$19:B37,"<>"),"")} -> 13 | B37: 317 | C37: AYUDANTE DE LABORATORIO | D37: 3726 | E37: MEJIA CASTILLO RAFAEL | F37: DEPARTAMENTO DE CONTROL DE CALIDAD | G37: MECR780129HMCJSF02 | S37: H | T37: =IFERROR(VLOOKUP(O37, '[1]CURSOS 2025'!A:B, 2, FALSE), "") | U37: =SUM(' PLAN Y PROGRAMA ANUAL 2026'!$R37) -> 0
A38: {=IF(B38<>"",COUNTIF($B$19:B38,"<>"),"")} -> 14 | B38: 317 | C38: AYUDANTE DE LABORATORIO | D38: 1780 | E38: CASTILLO GARCÍA JUAN CARLOS | F38: DEPARTAMENTO DE CONTROL DE CALIDAD | G38: CAGJ681219HDFSRN07 | S38: H | T38: =IFERROR(VLOOKUP(O38, '[1]CURSOS 2025'!A:B, 2, FALSE), "") | U38: =SUM(' PLAN Y PROGRAMA ANUAL 2026'!$R38) -> 0
A39: {=IF(B39<>"",COUNTIF($B$19:B39,"<>"),"")} -> 15 | B39: 317 | C39: TÉCNICO QUÍMICO | D39: 206278 | E39: ACOSTA AGUILLÓN RAFAEL | F39: DEPARTAMENTO DE CONTROL DE CALIDAD | G39: AOAR960904HDFCGF00 | K39: X | L39: X | M39: X | N39: EN LINEA | O39: CUMPLIMIENTO DEL REQUISITO CALIBRACIÓN DE INSTRUMENTOS DE MEDICIÓN | P39: 46073 | Q39: 46073 | R39: 2 | S39: H | T39: S/COSTO | U39: =SUM(' PLAN Y PROGRAMA ANUAL 2026'!$R39:$R39) -> 2
A40: {=IF(B40<>"",COUNTIF($B$19:B40,"<>"),"")} -> 16 | B40: 317 | C40: TÉCNICO QUÍMICO | D40: 206269 | E40: OLVERA LÓPEZ BLANCA EUGENIA | F40: DEPARTAMENTO DE CONTROL DE CALIDAD | G40: OELB980510MMCLPL02 | K40: X | L40: X | M40: X | N40: EN LINEA | O40: CUMPLIMIENTO DEL REQUISITO CALIBRACIÓN DE INSTRUMENTOS DE MEDICIÓN | P40: 46073 | Q40: 46073 | R40: 2 | S40: M | T40: S/COSTO | U40: =SUM(R40:R41) -> 4
K41: X | L41: X | M41: X | N41: EN LINEA | O41: ISO 9001 : 2026 Y SUS NUEVOS REQUERIMENTOS | P41: 46071 | Q41: 46071 | R41: 2 | S41: M | T41: S/COSTO
A42: {=IF(B42<>"",COUNTIF($B$19:B42,"<>"),"")} -> 17 | B42: 317 | C42: ANALISTA | D42: 62019 | E42: BERMUDEZ ROJAS CLARA ISABEL | F42: DEPARTAMENTO DE CONTROL DE CALIDAD | G42: BERC961024MBSRJL08 | K42: X | L42: X | M42: X | N42: EN LINEA | O42: ISO 9001 : 2026 Y SUS NUEVOS REQUERIMENTOS | P42: 46071 | Q42: 46071 | R42: 2 | S42: M | T42: S/COSTO | U42: =SUM(' PLAN Y PROGRAMA ANUAL 2026'!$R42:$R43) -> 4
A43: {=IF(B43<>"",COUNTIF($B$19:B43,"<>"),"")} | K43: X | L43: X | M43: X | N43: EN LINEA | O43: CUMPLIMIENTO DEL REQUISITO CALIBRACIÓN DE INSTRUMENTOS DE MEDICIÓN | P43: 46073 | Q43: 46073 | R43: 2 | S43: M | T43: S/COSTO
A44: {=IF(B44<>"",COUNTIF($B$19:B44,"<>"),"")} -> 18 | B44: 317 | C44: ANALISTA | D44: 62018 | E44: CRUZ MANRÍQUEZ JULIO MAXIMILIANO | F44: DEPARTAMENTO DE CONTROL DE CALIDAD | G44: CUMJ970109HBSRNL09 | K44: X | L44: X | M44: X | N44: EN LINEA | O44: ISO 9001 : 2026 Y SUS NUEVOS REQUERIMENTOS | P44: 46071 | Q44: 46071 | R44: 2 | S44: H | T44: S/COSTO | U44: =SUM(R44:R44) -> 2
A45: {=IF(B45<>"",COUNTIF($B$19:B45,"<>"),"")} -> 19 | B45: 317 | C45: TÉCNICO QUÍMICO | D45: 206264 | E45: ESPINOSA DÍAZ BRYAN EDWIN | F45: DEPARTAMENTO DE CONTROL DE CALIDAD | G45: EIDB940923HMCSZR00 | K45: X | L45: X | M45: X | N45: EN LINEA | O45: CUMPLIMIENTO DEL REQUISITO CALIBRACIÓN DE INSTRUMENTOS DE MEDICIÓN | P45: 46073 | Q45: 46073 | R45: 2 | S45: H | T45: S/COSTO | U45: =SUM(' PLAN Y PROGRAMA ANUAL 2026'!$R45:$R45) -> 2
A46: {=IF(B46<>"",COUNTIF($B$19:B46,"<>"),"")} -> 20 | B46: 317 | C46: TÉCNICO QUÍMICO | D46: 206295 | E46: MINGÜER URIBE ALDO ARIEL | F46: DEPARTAMENTO DE CONTROL DE CALIDAD | G46: MIUA950424HDFNRL04 | K46: X | L46: X | M46: X | N46: EN LINEA | O46: CUMPLIMIENTO DEL REQUISITO CALIBRACIÓN DE INSTRUMENTOS DE MEDICIÓN | P46: 46073 | Q46: 46073 | R46: 2 | S46: H | T46: S/COSTO | U46: =SUM(' PLAN Y PROGRAMA ANUAL 2026'!$R46:$R46) -> 2
A47: {=IF(B47<>"",COUNTIF($B$19:B47,"<>"),"")} -> 21 | B47: 317 | C47: TÉCNICO QUÍMICO | D47: 206298 | E47: GARCIA CHAVEZ DARIANA | F47: DEPARTAMENTO DE CONTROL DE CALIDAD | G47: GACD000131MDFRHRA6 | S47: M | T47: =IFERROR(VLOOKUP(O47, '[1]CURSOS 2025'!A:B, 2, FALSE), "") | U47: =SUM(R47:R47) -> 0
A48: {=IF(B48<>"",COUNTIF($B$19:B48,"<>"),"")} -> 22 | B48: 317 | C48: TÉCNICO QUÍMICO | D48: 206297 | E48: MILDRED BERENICE MOLINA LEONOR | F48: DEPARTAMENTO DE CONTROL DE CALIDAD | G48: MOLM000221MDFLNLA5 | S48: M | T48: =IFERROR(VLOOKUP(O48, '[1]CURSOS 2025'!A:B, 2, FALSE), "") | U48: =SUM(R48:R48) -> 0
A49: {=IF(B49<>"",COUNTIF($B$19:B49,"<>"),"")} -> 23 | B49: 317 | C49: AYUDANTE DE LABORATORIO | D49: 3952 | E49: MARTÍNEZ RITO CARLOS | F49: DEPARTAMENTO DE CONTROL DE CALIDAD | G49: MARC7901104HMCRTR06 | S49: H | U49: =SUM(R49) -> 0
...

Sheet CURSOS 2026
A2: Cursos | B2: $ | C2: MODALIDAD | D2: DURACIÓN
A3: ATENCIÓN SOCIOSANITARIA DE LAS PERSONAS MAYORES EN EL DOMICILIO. (FORTALECIMIENTO DE LAS COMPETENCIAS EN EL PERSONAL DE ENFERMERIA) | B3: S/COSTO | C3: EN LINEA | D3: 40
A4: OPERACIÓN DE MONTACARGAS | B4: S/COSTO | C4: EN LINEA | D4: 2
A5: CURSO PARA LA OPERACIÓN DEL MÓDULO DE PROCEDIMIENTOS DE CONTRATACIÓN EN LA PLATAFORMA COMPRAS MX | B5: S/COSTO | C5: EN LINEA | D5: 30
A6: REGULARIZACIÓN NORMATIVA EN MATERIA DE IMPACTO AMBIENTAL | B6: S/COSTO | C6: EN LINEA | D6: 2
A7: FÚTBOL SIN CORRER: FUNDAMENTOS PARA UN JUEGOLIMPIO Y SEGURO | B7: S/COSTO | C7: EN LINEA | D7: 2
A8: ABORDAJE DE TRASTORNOS POR CONSUMO DE SUSTANCIAS EN EL TERCER NIVEL DE ATENCIÓN CON BASE EN EL NUEVO MODELO MEXICANO | B8: S/COSTO | C8: EN LINEA | D8: 40
A9: DIVERSIDAD SEXUAL Y DERECHOS HUMANOS | B9: S/COSTO | C9: EN LINEA | D9: 30
A10: ACCIONES PARA ABORDAR RIESGOS Y OPORTUNIDADES | B10: S/COSTO | C10: EN LINEA | D10: 2
A11: EQUIPOS DE REFRIGERACIÓN Y AIRE ACONDICIONADO | B11: S/COSTO | C11: EN LINEA | D11: 2
A12: ISO 9001 : 2026 Y SUS NUEVOS REQUERIMENTOS | B12: S/COSTO | C12: EN LINEA | D12: 2
A13: CONTROL DE LA INFORMACIÓN DOCUMENTADA | B13: S/COSTO | C13: EN LINEA | D13: 2
A14: CUMPLIMIENTO DEL REQUISITO CALIBRACIÓN DE INSTRUMENTOS DE MEDICIÓN | B14: S/COSTO | C14: EN LINEA | D14: 2
... A38: PERSONAS CON DISCAPACIDAD;TRANSFORMANDO BARRERAS EN OPORTUNIDADES | B38: S/COSTO | C38: EN LINEA | D38: 30

Sheet CURSOS 2025
A1: 1 | B1: 2 | C1: 3 | D1: 4 | E1: 5
A2: Cursos | B2: $ | C2: MODALIDAD | D2: DURACIÓN
A3: ABORDAJE DE TRASTORNO POR CONSUMO DE SUSTANCIAS EN EL TERCER NIVEL DE ATENCIÓN CON BASE EN EL NUEVO MODELO MEXICANO | B3: S/COSTO | C3: EN LÍNEA | D3: 40
A4: ATENCIÓN A TRANSTORNOS MENTALES BASADA EN LA ESTRATEGIA mhGAP | B4: S/COSTO | C4: EN LÍNEA | D4: 40
A5: ESGUINCE DE TOBILLO Y MUÑECA | B5: S/COSTO | C5: EN LÍNEA | D5: 5
A6: ABC DE LA OBESIDAD | B6: S/COSTO | C6: EN LÍNEA | D6: 10
A7: PREVENCIÓN DE LA TRATA DE PERSONAS | B7: S/COSTO | C7: EN LÍNEA | D7: 40
A8: DERECHOS HUMANOS Y SALUD | B8: S/COSTO | C8: EN LÍNEA | D8: 40
A9: MARKETING DIGITAL I | B9: S/COSTO | C9: EN LÍNEA | D9: 40
A10: PLÁTICA DE INDUCCIÓN AL PERSONAL DE NUEVO INGRESO | B10: S/COSTO | C10: PRESENCIAL | D10: 1
A11: PLÁTICA DE SEGURIDAD E HIGIENE INDUSTRIAL AL PERSONAL DE NUEVO INGRESO | B11: S/COSTO | C11: PRESENCIAL | D11: 1
A12: EXCEL INTERMEDIO | B12: S/COSTO | C12: EN LÍNEA | D12: 2
A13: PLATICA DE INDUCCIÓN IMSS | B13: S/COSTO | C13: PRESENCIAL | D13: 1
A14: APLICACIONES DE LA INTELIGENCIA ARTIFICIAL EN EL USO Y OPTIMIZACIÓN DE SISTMAS DE ENERGÍA RENOVABLE | B14: S/COSTO | C14: PRESENCIAL | D14: 2
... A133: REDESCUBRIENDO AL IMSS | B133: S/COSTO | C133: EN LÍNEA | D133: 5
B134: S/COSTO
B135: S/COSTO
B136: S/COSTO
B137: S/COSTO
B138: S/COSTO
B139: S/COSTO
B140: S/COSTO
B141: S/COSTO
B142: S/COSTO
B143: S/COSTO
B144: S/COSTO
B145: S/COSTO
... B159: S/COSTO

Sheet Activos 2023
B2: PUESTO | C2: NÓMINA | D2: NOMBRE | E2: ÁREA | F2: CURP
B3: MÉDICO | C3: 206263 | D3: GUADARRAMA FERNANDEZ DE LARA SALVADOR | E3: RELACIONES INDUSTRIALES
B4: ANALISTA DE PROYECTO F | C4: 62018 | D4: CRUZ MANRIQUEZ JULIO MAXIMILIANO | E4: CONTROL DE CALIDAD
B5: ANALISTA DE PROYECTO F | C5: 62019 | D5: ROJAS BERMUDEZ CLARA ISABEL | E5: CONTROL DE CALIDAD
B6: AYUDANTE GENERAL | C6: 3961 | D6: MALDONADO OLVERA ELADIO | E6: PRODUCCIÓN
B7: AYUDANTE GENERAL | C7: 3962 | D7: PÉREZ CORONA JESÚS MANUEL | E7: PRODUCCIÓN
B8: AYUDANTE GENERAL | C8: 3963 | D8: SAUCEDO VILLALON JUAN JOSÉ | E8: PRODUCCIÓN
B9: AYUDANTE GENERAL | C9: 3966 | D9: RAMÍREZ CONTRERAS JULIO CESAR | E9: PRODUCCIÓN
B10: AYUDANTE GENERAL | C10: 3971 | D10: POBLANO ROSAS DIEGO ANTONIO | E10: PRODUCCIÓN
B11: AYUDANTE GENERAL | C11: 3973 | D11: HERRIANDE ALDANA MAXIMINA | E11: PRODUCCIÓN
B12: AYUDANTE GENERAL | C12: 3974 | D12: AGUILAR MORALES JOSÉ IVAN | E12: PRODUCCIÓN
B13: AYUDANTE GENERAL | C13: 3975 | D13: GONZÁLEZ VILCHIS JAIR | E13: PRODUCCIÓN
B14: AYUDANTE GENERAL | C14: 3976 | D14: RIOS GALINDO MARCOS | E14: PRODUCCIÓN
... B40: JEFE DE UNIDAD | C40: 206273 | D40: RAMIREZ CORTAZAR JULIO CESAR | E40: TALLER AUTOMOTRIZ

Sheet Cursos 2023
A1: Cursos
A2: ¿COMÓ ENTENDER EL PRESUPUESTO? EL GASTO PÚBLICO A TRAVÉS DE LOS DATOS | B2: S/COSTO | C2: EN LÍNEA | D2: 60 hrs
A3: ¿POR QUÉ AMAMOS DEMASIADO? PERO DEMASIADO MAL | B3: S/COSTO | C3: EN LÍNEA | D3: 2 hrs
A4: 5 "S" | B4: S/COSTO | C4: EN LÍNEA | D4: 3 hrs
A5: ABC DE LA OBESIDAD | B5: S/COSTO | C5: EN LÍNEA | D5: 10 hrs
A6: ACTIVACIÓN FÍSICA PARA EL PERSONAL QUE INTEGRA LA BRIGADA CONTRA INCENDIOS | B6: S/COSTO | C6: PRESENCIAL | D6: 1 hrs
A7: ACTIVACIÓN/PLÁTICA FÍSICA PARA EL PERSONAL QUE INTEGRA LA BRIGADA CONTRA INCENDIOS | B7: S/COSTO | C7: PRESENCIAL | D7: 1 hrs
A8: ACTIVIDAD FÍSICA: RETORNO SEGURO | B8: S/COSTO | C8: EN LÍNEA | D8: 3 hrs
A9: ACTIVIDADES CULTURALES: RETORNO SEGURO | B9: S/COSTO | C9: EN LÍNEA | D9: 5 hrs
A10: ADICCIONES Y SUS REPERCUCIONES EN EL ENTORNO LABORAL (TRABAJADORES) | B10: S/COSTO | C10: EN LÍNEA | D10: 10 hrs
A11: ADMINISTRACIÓN DE LOS ARCHIVOS DOCUMENTALES DE LICONSA | B11: S/COSTO | C11: EN LÍNEA | D11: 2 hrs
A12: ADMINISTRACIÓN PÚBLICA FEDERAL LIBRE DE VIOLENCIA. COMBATE AL ACOSO SEXUAL Y HOSTIGAMIENTO SEXUAL | B12: S/COSTO | C12: EN LÍNEA | D12: 8 hrs
A13: ALIMENTACIÓN, CLAVE PARA EL CONTROL DE LA DIABETES | B13: S/COSTO | C13: EN LÍNEA | D13: 20 hrs
... A186: YO DECIDO: MI SEXUALIDAD, MIS DECISIONES RESPONSABLES | B186: S/COSTO | C186: EN LÍNEA | D186: 2 hrs

Sheet BAJA 2024 (TRABAJADORES)
A1: 301 | B1: GERENTE | C1: 80181 | D1: DOMÍNGUEZ SANCHEZ JESÚS | E1: GERENCIA | F1: DOSJ520304HTSMNS08 | M1: =IF(N1="","",VLOOKUP(N1,'CURSOS 2025'!$A$3:$D$199,3,FALSE)) | Q1: =IF(N1="","",VLOOKUP(N1,'CURSOS 2025'!$A$3:$D$199,4,FALSE)) | R1: M | S1: =IF(N1="","",VLOOKUP(N1,'CURSOS 2025'!$A$3:$B$199,2,FALSE))
A2: 301 | B2: JEFE DE UNIDAD | C2: 206275 | D2: MAGAÑA MADIEDO EMMANUEL | E2: GERENCIA | F2: MAME990722HMCGDM06 | M2: =IF(N2="","",VLOOKUP(N2,'CURSOS 2025'!$A$3:$D$199,3,FALSE)) | Q2: =IF(N2="","",VLOOKUP(N2,'CURSOS 2025'!$A$3:$D$199,4,FALSE)) | R2: M | S2: =IF(N2="","",VLOOKUP(N2,'CURSOS 2025'!$A$3:$B$199,2,FALSE))
A3: 301 | B3: COORDINADOR GENERAL | C3: 206227 | D3: RAMOS OLIVARES MARIA DEL SOCORRO | E3: GERENCIA | F3: RAOS620418MHGMLC04 | M3: =IF(N3="","",VLOOKUP(N3,'CURSOS 2025'!$A$3:$D$199,3,FALSE)) | Q3: =IF(N3="","",VLOOKUP(N3,'CURSOS 2025'!$A$3:$D$199,4,FALSE)) | R3: F | S3: =IF(N3="","",VLOOKUP(N3,'CURSOS 2025'!$A$3:$B$199,2,FALSE))
A4: 301 | B4: JEFE DE UNIDAD | C4: 206228 | D4: PADILLA CONTRERAS JENNIFER | E4: GERENCIA | F4: PACJ910310MMCDNN05 | M4: =IF(N4="","",VLOOKUP(N4,'CURSOS 2025'!$A$3:$D$199,3,FALSE)) | Q4: =IF(N4="","",VLOOKUP(N4,'CURSOS 2025'!$A$3:$D$199,4,FALSE)) | R4: F | S4: =IF(N4="","",VLOOKUP(N4,'CURSOS 2025'!$A$3:$B$199,2,FALSE))
A5: 301 | B5: AUXILIAR PROYECTO E | C5: 62016 | D5: LOPEZ PADILLA ILSE JOCELYN | E5: GERENCIA | F5: LOPI960114MDFPDL08 | M5: =IF(N5="","",VLOOKUP(N5,'CURSOS 2025'!$A$3:$D$199,3,FALSE)) | Q5: =IF(N5="","",VLOOKUP(N5,'CURSOS 2025'!$A$3:$D$199,4,FALSE)) | R5: F | S5: =IF(N5="","",VLOOKUP(N5,'CURSOS 2025'!$A$3:$B$199,2,FALSE))
A6: 317 | B6: QUIMICO | C6: 20502 | D6: RIVERA ORDOÑEZ JOSÉ ROBERTO | E6: CONTROL DE CALIDAD | F6: RIOR611005HGRVRB05 | M6: =IF(N6="","",VLOOKUP(N6,'CURSOS 2025'!$A$3:$D$199,3,FALSE)) | Q6: =IF(N6="","",VLOOKUP(N6,'CURSOS 2025'!$A$3:$D$199,4,FALSE)) | R6: M | S6: =IF(N6="","",VLOOKUP(N6,'CURSOS 2025'!$A$3:$B$199,2,FALSE))
A7: 317 | B7: ANALISTA DE PROYECTO F | C7: 62018 | D7: CRUZ MANRIQUEZ JULIO MAXIMILIANO | E7: CONTROL DE CALIDAD | F7: CUMJ970109HBSRNL09 | M7: =IF(N7="","",VLOOKUP(N7,'CURSOS 2025'!$A$3:$D$199,3,FALSE)) | Q7: =IF(N7="","",VLOOKUP(N7,'CURSOS 2025'!$A$3:$D$199,4,FALSE)) | R7: M | S7: =IF(N7="","",VLOOKUP(N7,'CURSOS 2025'!$A$3:$B$199,2,FALSE))
A8: 317 | B8: ANALISTA DE PROYECTO F | C8: 62019 | D8: ROJAS BERMUDEZ CLARA ISABEL | E8: CONTROL DE CALIDAD | F8: BERC961024MBSRJL08 | M8: =IF(N8="","",VLOOKUP(N8,'CURSOS 2025'!$A$3:$D$199,3,FALSE)) | Q8: =IF(N8="","",VLOOKUP(N8,'CURSOS 2025'!$A$3:$D$199,4,FALSE)) | R8: F | S8: =IF(N8="","",VLOOKUP(N8,'CURSOS 2025'!$A$3:$B$199,2,FALSE))
A9: 317 | B9: OPERADOR DE SERVICIOS B | C9: 62024 | D9: SUÁREZ SUÁREZ ANGELES ELIZABETH | E9: CONTROL DE CALIDAD | F9: SUSA960917MVZRRN04 | M9: =IF(N9="","",VLOOKUP(N9,'CURSOS 2025'!$A$3:$D$199,3,FALSE)) | Q9: =IF(N9="","",VLOOKUP(N9,'CURSOS 2025'!$A$3:$D$199,4,FALSE)) | R9: F | S9: =IF(N9="","",VLOOKUP(N9,'CURSOS 2025'!$A$3:$B$199,2,FALSE))
A10: 234 | B10: JEFE DE UNIDAD | C10: 206250 | D10: ALVAREZ TOSTADO HERNÁNDEZ JESSICA MICHEL | E10: TALLER AUTOMOTRIZ | F10: AAHJ960519MDFLRS02 | M10: =IF(N10="","",VLOOKUP(N10,'CURSOS 2025'!$A$3:$D$199,3,FALSE)) | Q10: =IF(N10="","",VLOOKUP(N10,'CURSOS 2025'!$A$3:$D$199,4,FALSE)) | R10: F | S10: =IF(N10="","",VLOOKUP(N10,'CURSOS 2025'!$A$3:$B$199,2,FALSE))
A11: 234 | B11: MECANICO DIESEL | C11: 1671 | D11: LÓPEZ RUBIO ENRIQUE | E11: TALLER AUTOMOTRIZ | F11: LORE601113HDFPBN05 | M11: =IF(N11="","",VLOOKUP(N11,'CURSOS 2025'!$A$3:$D$199,3,FALSE)) | Q11: =IF(N11="","",VLOOKUP(N11,'CURSOS 2025'!$A$3:$D$199,4,FALSE)) | R11: M | S11: =IF(N11="","",VLOOKUP(N11,'CURSOS 2025'!$A$3:$B$199,2,FALSE))
A12: 615 | B12: OPERADOR DE SERVICIOS B | C12: 62025 | D12: MIRANDA ALCÁNTARA DANIELA KARINA | E12: ATENCIÓN Y SERVICIOS A CONCESIONARIOS | F12: MIAD010628MDFRLNA2 | M12: =IF(N12="","",VLOOKUP(N12,'CURSOS 2025'!$A$3:$D$199,3,FALSE)) | Q12: =IF(N12="","",VLOOKUP(N12,'CURSOS 2025'!$A$3:$D$199,4,FALSE)) | R12: F | S12: =IF(N12="","",VLOOKUP(N12,'CURSOS 2025'!$A$3:$B$199,2,FALSE))
A13: 247 | B13: COSTEADOR DE ORDENES DE TRABAJO | C13: 5933 | D13: BASURTO GUZMÁN RICARDO | E13: ADMINISTRACIÓN OPERATIVA DEL PADRON | F13: BAGR630804HDFSZC07 | M13: =IF(N13="","",VLOOKUP(N13,'CURSOS 2025'!$A$3:$D$199,3,FALSE)) | Q13: =IF(N13="","",VLOOKUP(N13,'CURSOS 2025'!$A$3:$D$199,4,FALSE)) | R13: M | S13: =IF(N13="","",VLOOKUP(N13,'CURSOS 2025'!$A$3:$B$199,2,FALSE))
A14: 247 | B14: AUXILIAR ADMINISTRATIVO | C14: 555 | D14: HERNÁNDEZ MENDEZ MARIA ISABEL | E14: ADMINISTRACIÓN OPERATIVA DEL PADRON | F14: HEMI720223MOCRNS09 | M14: =IF(N14="","",VLOOKUP(N14,'CURSOS 2025'!$A$3:$D$199,3,FALSE)) | Q14: =IF(N14="","",VLOOKUP(N14,'CURSOS 2025'!$A$3:$D$199,4,FALSE)) | R14: F | S14: =IF(N14="","",VLOOKUP(N14,'CURSOS 2025'!$A$3:$B$199,2,FALSE))
A15: 247 | B15: AUXILIAR ADMINISTRATIVO | C15: 6118 | D15: SÀNCHEZ ARELLANO PABLO | E15: COORDINACIÓN ACTUALIZACIÓN DEL PADRON | F15: SAAP950220HMCNRB03 | M15: =IF(N15="","",VLOOKUP(N15,'CURSOS 2025'!$A$3:$D$199,3,FALSE)) | Q15: =IF(N15="","",VLOOKUP(N15,'CURSOS 2025'!$A$3:$D$199,4,FALSE)) | R15: M | S15: =IF(N15="","",VLOOKUP(N15,'CURSOS 2025'!$A$3:$B$199,2,FALSE))
A16: 247 | B16: CORDINADORA | C16: 20548 | D16: CORREA PIMENTEL ANA MARTHA | E16: CORDINADORA PADRÓN | F16: COPA520110MDFRMN02 | M16: =IF(N16="","",VLOOKUP(N16,'CURSOS 2025'!$A$3:$D$199,3,FALSE)) | Q16: =IF(N16="","",VLOOKUP(N16,'CURSOS 2025'!$A$3:$D$199,4,FALSE)) | R16: F | S16: =IF(N16="","",VLOOKUP(N16,'CURSOS 2025'!$A$3:$B$199,2,FALSE))
A17: 247 | B17: AUXILIAR ADMINISTRATIVO | C17: 5953 | D17: PACHECO MORALES JULIO CESAR | E17: COORDINACIÓN ACTUALIZACIÓN DEL PADRON | F17: PAMJ850601HMCCRL06 | M17: =IF(N17="","",VLOOKUP(N17,'CURSOS 2025'!$A$3:$D$199,3,FALSE)) | Q17: =IF(N17="","",VLOOKUP(N17,'CURSOS 2025'!$A$3:$D$199,4,FALSE)) | R17: M | S17: =IF(N17="","",VLOOKUP(N17,'CURSOS 2025'!$A$3:$B$199,2,FALSE))
A18: 248 | B18: PROMOTOR SOCIAL | C18: 206101 | D18: MIRANDA VICENTE GREYCE IVVANOVA | E18: COORDINACIÓN TLALNEPANTLA SECTOR I | F18: MIVG881227MDFRCR12 | M18: =IF(N18="","",VLOOKUP(N18,'CURSOS 2025'!$A$3:$D$199,3,FALSE)) | Q18: =IF(N18="","",VLOOKUP(N18,'CURSOS 2025'!$A$3:$D$199,4,FALSE)) | R18: F | S18: =IF(N18="","",VLOOKUP(N18,'CURSOS 2025'!$A$3:$B$199,2,FALSE))
A19: 248 | B19: PROMOTOR SOCIAL | C19: 20891 | D19: NUÑEZ HERNÁNDEZ MIRNA IRAIS | E19: COORDINACIÓN TLALNEPANTLA SECTOR I | F19: NUHM591120MDFXRR04 | M19: =IF(N19="","",VLOOKUP(N19,'CURSOS 2025'!$A$3:$D$199,3,FALSE)) | Q19: =IF(N19="","",VLOOKUP(N19,'CURSOS 2025'!$A$3:$D$199,4,FALSE)) | R19: F | S19: =IF(N19="","",VLOOKUP(N19,'CURSOS 2025'!$A$3:$B$199,2,FALSE))
A20: 248 | B20: PROMOTOR SOCIAL | C20: 20440 | D20: MEJIA GARCÍA FRANCISCO | E20: COORDINACIÓN TLALNEPANTLA DECTOR I | M20: =IF(N20="","",VLOOKUP(N20,'CURSOS 2025'!$A$3:$D$199,3,FALSE)) | Q20: =IF(N20="","",VLOOKUP(N20,'CURSOS 2025'!$A$3:$D$199,4,FALSE)) | R20: M | S20: =IF(N20="","",VLOOKUP(N20,'CURSOS 2025'!$A$3:$B$199,2,FALSE))
A21: 248 | B21: COORDINADOR DE SECTOR OPERATIVO | C21: 20344 | D21: HERNÁNDEZ LOYOLA JORGE | E21: COORDINACIÓN TLALNEPANTLA SECTOR II | F21: HELJ540423HOCRYR05 | M21: =IF(N21="","",VLOOKUP(N21,'CURSOS 2025'!$A$3:$D$199,3,FALSE)) | Q21: =IF(N21="","",VLOOKUP(N21,'CURSOS 2025'!$A$3:$D$199,4,FALSE)) | R21: M | S21: =IF(N21="","",VLOOKUP(N21,'CURSOS 2025'!$A$3:$B$199,2,FALSE))
A22: 248 | B22: SUPERVISOR OPERATIVO | C22: 20214 | D22: FLORES CAMPOS CARLOS JAIME | E22: COORDINACIÓN TLALNEPANTLA SECTOR II | F22: FOCC550411HDFLMR01 | M22: =IF(N22="","",VLOOKUP(N22,'CURSOS 2025'!$A$3:$D$199,3,FALSE)) | Q22: =IF(N22="","",VLOOKUP(N22,'CURSOS 2025'!$A$3:$D$199,4,FALSE)) | R22: M | S22: =IF(N22="","",VLOOKUP(N22,'CURSOS 2025'!$A$3:$B$199,2,FALSE))
A23: 248 | B23: PROMOTOR SOCIAL | C23: 20812 | D23: LÓPEZ SÁNCHEZ DORA GUADALUPE | E23: COORDINACIÓN TLALNEPANTLA SECTOR III | F23: LOSD571211MDFPNR01 | M23: =IF(N23="","",VLOOKUP(N23,'CURSOS 2025'!$A$3:$D$199,3,FALSE)) | Q23: =IF(N23="","",VLOOKUP(N23,'CURSOS 2025'!$A$3:$D$199,4,FALSE)) | R23: F | S23: =IF(N23="","",VLOOKUP(N23,'CURSOS 2025'!$A$3:$B$199,2,FALSE))
A24: 227 | B24: JEFE DE UNIDAD | C24: 206191 | D24: ANAYA VAZQUEZ CESAR | E24: DISTRIBUCIÓN | F24: AAVC751104HDFNZS03 | M24: =IF(N24="","",VLOOKUP(N24,'CURSOS 2025'!$A$3:$D$199,3,FALSE)) | Q24: =IF(N24="","",VLOOKUP(N24,'CURSOS 2025'!$A$3:$D$199,4,FALSE)) | R24: M | S24: =IF(N24="","",VLOOKUP(N24,'CURSOS 2025'!$A$3:$B$199,2,FALSE))
A25: 227 | B25: AYUDANTE GENERAL | C25: 3910 | D25: VAZQUEZ NAVARRO JUAN CARLOS | E25: DISTRIBUCIÓN | F25: VANJ700120HDFZVN08 | M25: =IF(N25="","",VLOOKUP(N25,'CURSOS 2025'!$A$3:$D$199,3,FALSE)) | Q25: =IF(N25="","",VLOOKUP(N25,'CURSOS 2025'!$A$3:$D$199,4,FALSE)) | R25: M | S25: =IF(N25="","",VLOOKUP(N25,'CURSOS 2025'!$A$3:$B$199,2,FALSE))
A26: 227 | B26: DESPACHADOR ANDEN | C26: 3652 | D26: LÓPEZ HERNÁNDEZ LAZARO | E26: COORDINACIÓN DE ATENCIÓN A TRANSPORTISTAS Y CONC. | F26: LOHL820504HCSPRZ07 | M26: =IF(N26="","",VLOOKUP(N26,'CURSOS 2025'!$A$3:$D$199,3,FALSE)) | Q26: =IF(N26="","",VLOOKUP(N26,'CURSOS 2025'!$A$3:$D$199,4,FALSE)) | R26: M | S26: =IF(N26="","",VLOOKUP(N26,'CURSOS 2025'!$A$3:$B$199,2,FALSE))
A27: 233 | B27: SUPERVISOR DE DISTRIBUCION EN CAMPO | C27: 1403 | D27: HERNÁNDEZ MENDOZA JOSÉ GUADALUPE | E27: DISTRIBUCIÓN | F27: HEMG650228HMCRND08 | M27: =IF(N27="","",VLOOKUP(N27,'CURSOS 2025'!$A$3:$D$199,3,FALSE)) | Q27: =IF(N27="","",VLOOKUP(N27,'CURSOS 2025'!$A$3:$D$199,4,FALSE)) | R27: M | S27: =IF(N27="","",VLOOKUP(N27,'CURSOS 2025'!$A$3:$B$199,2,FALSE))
A28: 233 | B28: SUPERVISOR DE DISTRIBUCION EN CAMPO | C28: 20325 | D28: VITAL LAZARO ARTURO | E28: COORDINACIÓN DISTRIBUCIÓN SECTOR I | F28: VILA571215HMSTZR00 | M28: =IF(N28="","",VLOOKUP(N28,'CURSOS 2025'!$A$3:$D$199,3,FALSE)) | Q28: =IF(N28="","",VLOOKUP(N28,'CURSOS 2025'!$A$3:$D$199,4,FALSE)) | R28: M | S28: =IF(N28="","",VLOOKUP(N28,'CURSOS 2025'!$A$3:$B$199,2,FALSE))
A29: 228 | B29: SUPERVISOR DE CONTROL DE PARQUE VEHICULAR | C29: 20876 | D29: GARCÍA PARRALES JOSÉ DE JESUS | E29: MANTENIMIENTO CIVIL A LECHERIAS | F29: GAPJ540513HDFRRS01 | M29: =IF(N29="","",VLOOKUP(N29,'CURSOS 2025'!$A$3:$D$199,3,FALSE)) | Q29: =IF(N29="","",VLOOKUP(N29,'CURSOS 2025'!$A$3:$D$199,4,FALSE)) | R29: M | S29: =IF(N29="","",VLOOKUP(N29,'CURSOS 2025'!$A$3:$B$199,2,FALSE))
A30: 228 | B30: TECNICO EN MANTENIMIENTO | C30: 1925 | D30: DE LA ROSA ALEGRIA FLORENCIO | E30: COORDINACIÓN DE MANTENIMIENTO CIVIL REGIÓN I | F30: ROAF611029 HOCSLL01 | M30: =IF(N30="","",VLOOKUP(N30,'CURSOS 2025'!$A$3:$D$199,3,FALSE)) | Q30: =IF(N30="","",VLOOKUP(N30,'CURSOS 2025'!$A$3:$D$199,4,FALSE)) | R30: M | S30: =IF(N30="","",VLOOKUP(N30,'CURSOS 2025'!$A$3:$B$199,2,FALSE))
A31: 228 | B31: TECNICO EN MANTENIMIENTO | C31: 1552 | D31: PÉREZ HERNÁNDEZ JOSÉ GUADALUPE | E31: COORDINACIÓN DE MANTENIMIENTO CIVIL REGIÓN I | F31: PEHG661209 HMCRRD02 | M31: =IF(N31="","",VLOOKUP(N31,'CURSOS 2025'!$A$3:$D$199,3,FALSE)) | Q31: =IF(N31="","",VLOOKUP(N31,'CURSOS 2025'!$A$3:$D$199,4,FALSE)) | R31: M | S31: =IF(N31="","",VLOOKUP(N31,'CURSOS 2025'!$A$3:$B$199,2,FALSE))
A32: 228 | B32: ALBAÑIL | C32: 3548 | D32: PRIETO OSORNIO ALEJANDRO | E32: COORDINACIÓN DE MANTENIMIENTO CIVIL REGIÓN I | F32: PIOA590221HDFRSL02 | M32: =IF(N32="","",VLOOKUP(N32,'CURSOS 2025'!$A$3:$D$199,3,FALSE)) | Q32: =IF(N32="","",VLOOKUP(N32,'CURSOS 2025'!$A$3:$D$199,4,FALSE)) | R32: M | S32: =IF(N32="","",VLOOKUP(N32,'CURSOS 2025'!$A$3:$B$199,2,FALSE))
... A43: 328 | B43: AYUDANTE ESPECIALIZADO | C43: 3907 | D43: PADRÓN VAZQUEZ JORGE MANUEL | E43: PRODUCCIÓN | F43: PAVJ810816HDFDZR08 | M43: =IF(N43="","",VLOOKUP(N43,'CURSOS 2025'!$A$3:$D$199,3,FALSE)) | Q43: =IF(N43="","",VLOOKUP(N43,'CURSOS 2025'!$A$3:$D$199,4,FALSE)) | R43: M | S43: =IF(N43="","",VLOOKUP(N43,'CURSOS 2025'!$A$3:$B$199,2,FALSE))
A44: 329 | B44: MECÁNICO SUSPENSIÓN | C44: 3800 | D44: TREJO CORREA RENE | E44: TALLER AUTOMOTRIZ | F44: TECR920715HDFRRN08 | J44: X | K44: X | L44: X | M44: =IF(N44="","",VLOOKUP(N44,'CURSOS 2025'!$A$3:$D$199,3,FALSE)) -> #N/A | N44: HOJALATERIA Y PINTURA | O44: 45334 | P44: 45338 | Q44: =IF(N44="","",VLOOKUP(N44,'CURSOS 2025'!$A$3:$D$199,4,FALSE)) -> #N/A | R44: M | S44: =IF(N44="","",VLOOKUP(N44,'CURSOS 2025'!$A$3:$B$199,2,FALSE)) -> #N/A
A45: 328 | B45: OPERADOR DE MAQUINA | C45: 3505 | D45: GONZÁLEZ REYES IVAN | E45: PRODUCCIÓN | F45: GORI811230HDFNYV02 | M45: =IF(N45="","",VLOOKUP(N45,'CURSOS 2025'!$A$3:$D$199,3,FALSE)) | Q45: =IF(N45="","",VLOOKUP(N45,'CURSOS 2025'!$A$3:$D$199,4,FALSE)) | R45: M | S45: =IF(N45="","",VLOOKUP(N45,'CURSOS 2025'!$A$3:$B$199,2,FALSE))
A46: 328 | B46: OPERADOR DE REHIDRATADO | C46: 3707 | D46: DURAN GÓMEZ LEONARDO | E46: PRODUCCIÓN | F46: DUGL581015HVZRMN04 | M46: =IF(N46="","",VLOOKUP(N46,'CURSOS 2025'!$A$3:$D$199,3,FALSE)) | Q46: =IF(N46="","",VLOOKUP(N46,'CURSOS 2025'!$A$3:$D$199,4,FALSE)) | R46: M | S46: =IF(N46="","",VLOOKUP(N46,'CURSOS 2025'!$A$3:$B$199,2,FALSE))
A47: 328 | B47: OPERADOR DE MAQUINA | C47: 1262 | D47: TETELPA CARIÑO TEODULO | E47: PRODUCCIÓN | F47: TECT630217HVZTRD05 | M47: =IF(N47="","",VLOOKUP(N47,'CURSOS 2025'!$A$3:$D$199,3,FALSE)) | Q47: =IF(N47="","",VLOOKUP(N47,'CURSOS 2025'!$A$3:$D$199,4,FALSE)) | R47: M | S47: =IF(N47="","",VLOOKUP(N47,'CURSOS 2025'!$A$3:$B$199,2,FALSE))
A48: 328 | B48: AYUDANTE GENERAL | C48: 3977 | D48: CISNEROS FLORES GABRIEL | E48: PRODUCCIÓN | F48: CIFG920405HMCSLB03 | M48: =IF(N48="","",VLOOKUP(N48,'CURSOS 2025'!$A$3:$D$199,3,FALSE)) | Q48: =IF(N48="","",VLOOKUP(N48,'CURSOS 2025'!$A$3:$D$199,4,FALSE)) | R48: M | S48: =IF(N48="","",VLOOKUP(N48,'CURSOS 2025'!$A$3:$B$199,2,FALSE))
A49: 328 | B49: AYUDANTE GENERAL | C49: 3995 | D49: DURAN RODRÍGUEZ ANDRES ARIEL | E49: PRODUCCIÓN | F49: DURA031227HDFRDNA7 | M49: =IF(N49="","",VLOOKUP(N49,'CURSOS 2025'!$A$3:$D$199,3,FALSE)) | Q49: =IF(N49="","",VLOOKUP(N49,'CURSOS 2025'!$A$3:$D$199,4,FALSE)) | R49: M | S49: =IF(N49="","",VLOOKUP(N49,'CURSOS 2025'!$A$3:$B$199,2,FALSE))
A50: 328 | B50: AYUDANTE GENERAL | C50: 1996 | D50: ENSALDO SEGURA HERIBERTO | E50: PRODUCCIÓN | F50: EASH730810HDFNGR04 | M50: =IF(N50="","",VLOOKUP(N50,'CURSOS 2025'!$A$3:$D$199,3,FALSE)) | Q50: =IF(N50="","",VLOOKUP(N50,'CURSOS 2025'!$A$3:$D$199,4,FALSE)) | R50: M | S50: =IF(N50="","",VLOOKUP(N50,'CURSOS 2025'!$A$3:$B$199,2,FALSE))
...
